{
    "registryname": "lava_pump",
    "localizedname": "Lava Pump",
    "requires-blueprint": true,
    "parts": [
        {
            "x": -2,
            "y": -2,
            "z": -1,
            "elements": [
                "chisel:technicalnew@2"
            ]
        },
        {
            "x": -1,
            "y": 0,
            "z": 0,
            "elements": [
                "chisel:technicalnew@6"
            ]
        },
        {
            "x": -2,
            "y": 0,
            "z": 2,
            "elements": [
                "chisel:technicalnew@2"
            ]
        },
        {
            "x": 1,
            "y": 0,
            "z": 0,
            "elements": [
                "chisel:technicalnew@6"
            ]
        },
        {
            "x": -2,
            "y": 0,
            "z": 0,
            "elements": [
                "chisel:technicalnew@2"
            ]
        },
        {
            "x": -1,
            "y": 0,
            "z": 2,
            "elements": [
                "chisel:technicalnew@6"
            ]
        },
        {
            "x": -3,
            "y": -2,
            "z": -1,
            "elements": [
                "hbm:deco_tungsten@0"
            ]
        },
        {
            "x": 2,
            "y": 0,
            "z": 0,
            "elements": [
                "chisel:technicalnew@2"
            ]
        },
        {
            "x": 0,
            "y": 0,
            "z": 2,
            "elements": [
                "modularmachinery:blockfluidoutputhatch"
            ]
        },
        {
            "x": -3,
            "y": -2,
            "z": 3,
            "elements": [
                "hbm:deco_tungsten@0"
            ]
        },
        {
            "x": 0,
            "y": -2,
            "z": 1,
            "elements": [
                "hbm:drill_pipe@0"
            ]
        },
        {
            "x": 1,
            "y": 0,
            "z": 2,
            "elements": [
                "chisel:technicalnew@6"
            ]
        },
        {
            "x": -2,
            "y": -2,
            "z": 3,
            "elements": [
                "chisel:technicalnew@2"
            ]
        },
        {
            "x": 2,
            "y": 0,
            "z": 2,
            "elements": [
                "chisel:technicalnew@2"
            ]
        },
        {
            "x": -1,
            "y": -2,
            "z": 3,
            "elements": [
                "hbm:deco_tungsten@0"
            ]
        },
        {
            "x": 1,
            "y": -2,
            "z": 3,
            "elements": [
                "hbm:deco_tungsten@0"
            ]
        },
        {
            "x": 2,
            "y": -2,
            "z": 3,
            "elements": [
                "chisel:technicalnew@2"
            ]
        },
        {
            "x": 3,
            "y": -2,
            "z": 3,
            "elements": [
                "hbm:deco_tungsten@0"
            ]
        },
        {
            "x": 3,
            "y": -3,
            "z": -1,
            "elements": [
                "hbm:deco_tungsten@0"
            ]
        },
        {
            "x": 2,
            "y": -3,
            "z": -1,
            "elements": [
                "hbm:deco_tungsten@0"
            ]
        },
        {
            "x": 1,
            "y": -3,
            "z": -1,
            "elements": [
                "hbm:deco_tungsten@0"
            ]
        },
        {
            "x": -2,
            "y": 1,
            "z": 0,
            "elements": [
                "hbm:deco_tungsten@0"
            ]
        },
        {
            "x": -1,
            "y": 1,
            "z": 0,
            "elements": [
                "chisel:technicalnew@2"
            ]
        },
        {
            "x": -1,
            "y": -3,
            "z": -1,
            "elements": [
                "hbm:deco_tungsten@0"
            ]
        },
        {
            "x": 0,
            "y": 1,
            "z": 0,
            "elements": [
                "hbm:deco_tungsten@0"
            ]
        },
        {
            "x": -2,
            "y": -3,
            "z": -1,
            "elements": [
                "hbm:deco_tungsten@0"
            ]
        },
        {
            "x": -2,
            "y": 1,
            "z": 2,
            "elements": [
                "hbm:deco_tungsten@0"
            ]
        },
        {
            "x": 2,
            "y": 1,
            "z": -1,
            "elements": [
                "hbm:deco_tungsten@0"
            ]
        },
        {
            "x": 1,
            "y": 1,
            "z": 0,
            "elements": [
                "chisel:technicalnew@2"
            ]
        },
        {
            "x": -1,
            "y": 1,
            "z": 2,
            "elements": [
                "chisel:technicalnew@2"
            ]
        },
        {
            "x": -3,
            "y": -3,
            "z": -1,
            "elements": [
                "hbm:deco_tungsten@0"
            ]
        },
        {
            "x": 1,
            "y": 1,
            "z": -1,
            "elements": [
                "hbm:deco_tungsten@0"
            ]
        },
        {
            "x": 0,
            "y": 1,
            "z": 2,
            "elements": [
                "hbm:deco_tungsten@0"
            ]
        },
        {
            "x": 0,
            "y": 1,
            "z": -1,
            "elements": [
                "hbm:deco_tungsten@0"
            ]
        },
        {
            "x": 2,
            "y": 1,
            "z": 0,
            "elements": [
                "hbm:deco_tungsten@0"
            ]
        },
        {
            "x": 0,
            "y": -1,
            "z": 1,
            "elements": [
                "hbm:drill_pipe@0"
            ]
        },
        {
            "x": -2,
            "y": -1,
            "z": 3,
            "elements": [
                "chisel:technicalnew@2"
            ]
        },
        {
            "x": 1,
            "y": 1,
            "z": 2,
            "elements": [
                "chisel:technicalnew@2"
            ]
        },
        {
            "x": -1,
            "y": 1,
            "z": -1,
            "elements": [
                "hbm:deco_tungsten@0"
            ]
        },
        {
            "x": -2,
            "y": -3,
            "z": 2,
            "elements": [
                "hbm:deco_tungsten@0"
            ]
        },
        {
            "x": -2,
            "y": 1,
            "z": -1,
            "elements": [
                "hbm:deco_tungsten@0"
            ]
        },
        {
            "x": 2,
            "y": 1,
            "z": 2,
            "elements": [
                "hbm:deco_tungsten@0"
            ]
        },
        {
            "x": -2,
            "y": -3,
            "z": 4,
            "elements": [
                "hbm:deco_tungsten@0"
            ]
        },
        {
            "x": 2,
            "y": -1,
            "z": 3,
            "elements": [
                "chisel:technicalnew@2"
            ]
        },
        {
            "x": 2,
            "y": -3,
            "z": 2,
            "elements": [
                "hbm:deco_tungsten@0"
            ]
        },
        {
            "x": 2,
            "y": -3,
            "z": 4,
            "elements": [
                "hbm:deco_tungsten@0"
            ]
        },
        {
            "x": 2,
            "y": -2,
            "z": 0,
            "elements": [
                "hbm:deco_tungsten@0"
            ]
        },
        {
            "x": 2,
            "y": -2,
            "z": -2,
            "elements": [
                "hbm:deco_tungsten@0"
            ]
        },
        {
            "x": 2,
            "y": 0,
            "z": -1,
            "elements": [
                "chisel:technicalnew@2"
            ]
        },
        {
            "x": 1,
            "y": 0,
            "z": -1,
            "elements": [
                "chisel:technicalnew@2"
            ]
        },
        {
            "x": -2,
            "y": -2,
            "z": 0,
            "elements": [
                "hbm:deco_tungsten@0"
            ]
        },
        {
            "x": -1,
            "y": 0,
            "z": 1,
            "elements": [
                "modularmachinery:blockenergyinputhatch"
            ]
        },
        {
            "x": -1,
            "y": 0,
            "z": -1,
            "elements": [
                "chisel:technicalnew@2"
            ]
        },
        {
            "x": -2,
            "y": 0,
            "z": 3,
            "elements": [
                "chisel:technicalnew@2"
            ]
        },
        {
            "x": 0,
            "y": 0,
            "z": 1,
            "elements": [
                "advancedrocketry:drill@3"
            ]
        },
        {
            "x": -2,
            "y": -2,
            "z": -2,
            "elements": [
                "hbm:deco_tungsten@0"
            ]
        },
        {
            "x": 1,
            "y": 0,
            "z": 1,
            "elements": [
                "chisel:technicalnew@6"
            ]
        },
        {
            "x": -1,
            "y": 0,
            "z": 3,
            "elements": [
                "chisel:technicalnew@2"
            ]
        },
        {
            "x": -2,
            "y": 0,
            "z": -1,
            "elements": [
                "chisel:technicalnew@2"
            ]
        },
        {
            "x": -2,
            "y": -2,
            "z": 2,
            "elements": [
                "hbm:deco_tungsten@0"
            ]
        },
        {
            "x": 2,
            "y": 0,
            "z": 1,
            "elements": [
                "chisel:technicalnew@2"
            ]
        },
        {
            "x": 1,
            "y": 0,
            "z": 3,
            "elements": [
                "chisel:technicalnew@2"
            ]
        },
        {
            "x": -2,
            "y": -2,
            "z": 4,
            "elements": [
                "hbm:deco_tungsten@0"
            ]
        },
        {
            "x": 2,
            "y": 0,
            "z": 3,
            "elements": [
                "chisel:technicalnew@2"
            ]
        },
        {
            "x": 2,
            "y": -2,
            "z": 2,
            "elements": [
                "hbm:deco_tungsten@0"
            ]
        },
        {
            "x": 2,
            "y": -2,
            "z": 4,
            "elements": [
                "hbm:deco_tungsten@0"
            ]
        },
        {
            "x": 2,
            "y": -3,
            "z": 0,
            "elements": [
                "hbm:deco_tungsten@0"
            ]
        },
        {
            "x": 2,
            "y": -3,
            "z": -2,
            "elements": [
                "hbm:deco_tungsten@0"
            ]
        },
        {
            "x": 2,
            "y": -1,
            "z": -1,
            "elements": [
                "chisel:technicalnew@2"
            ]
        },
        {
            "x": -2,
            "y": -3,
            "z": 0,
            "elements": [
                "hbm:deco_tungsten@0"
            ]
        },
        {
            "x": -2,
            "y": 1,
            "z": 1,
            "elements": [
                "hbm:deco_tungsten@0"
            ]
        },
        {
            "x": -1,
            "y": 1,
            "z": 1,
            "elements": [
                "hbm:deco_tungsten@0"
            ]
        },
        {
            "x": 0,
            "y": 1,
            "z": 1,
            "elements": [
                "modularmachinery:blockinputbus"
            ]
        },
        {
            "x": -2,
            "y": -3,
            "z": -2,
            "elements": [
                "hbm:deco_tungsten@0"
            ]
        },
        {
            "x": -2,
            "y": 1,
            "z": 3,
            "elements": [
                "hbm:deco_tungsten@0"
            ]
        },
        {
            "x": -2,
            "y": -1,
            "z": -1,
            "elements": [
                "chisel:technicalnew@2"
            ]
        },
        {
            "x": 1,
            "y": 1,
            "z": 1,
            "elements": [
                "hbm:deco_tungsten@0"
            ]
        },
        {
            "x": -1,
            "y": 1,
            "z": 3,
            "elements": [
                "hbm:deco_tungsten@0"
            ]
        },
        {
            "x": 0,
            "y": 1,
            "z": 3,
            "elements": [
                "hbm:deco_tungsten@0"
            ]
        },
        {
            "x": 2,
            "y": 1,
            "z": 1,
            "elements": [
                "hbm:deco_tungsten@0"
            ]
        },
        {
            "x": -3,
            "y": -3,
            "z": 3,
            "elements": [
                "hbm:deco_tungsten@0"
            ]
        },
        {
            "x": 1,
            "y": 1,
            "z": 3,
            "elements": [
                "hbm:deco_tungsten@0"
            ]
        },
        {
            "x": 0,
            "y": -3,
            "z": 1,
            "elements": [
                "hbm:drill_pipe@0"
            ]
        },
        {
            "x": -2,
            "y": -3,
            "z": 3,
            "elements": [
                "hbm:deco_tungsten@0"
            ]
        },
        {
            "x": 2,
            "y": 1,
            "z": 3,
            "elements": [
                "hbm:deco_tungsten@0"
            ]
        },
        {
            "x": -1,
            "y": -3,
            "z": 3,
            "elements": [
                "hbm:deco_tungsten@0"
            ]
        },
        {
            "x": 1,
            "y": -3,
            "z": 3,
            "elements": [
                "hbm:deco_tungsten@0"
            ]
        },
        {
            "x": 2,
            "y": -3,
            "z": 3,
            "elements": [
                "hbm:deco_tungsten@0"
            ]
        },
        {
            "x": 3,
            "y": -3,
            "z": 3,
            "elements": [
                "hbm:deco_tungsten@0"
            ]
        },
        {
            "x": 3,
            "y": -2,
            "z": -1,
            "elements": [
                "hbm:deco_tungsten@0"
            ]
        },
        {
            "x": 2,
            "y": -2,
            "z": -1,
            "elements": [
                "chisel:technicalnew@2"
            ]
        },
        {
            "x": 1,
            "y": -2,
            "z": -1,
            "elements": [
                "hbm:deco_tungsten@0"
            ]
        },
        {
            "x": -1,
            "y": -2,
            "z": -1,
            "elements": [
                "hbm:deco_tungsten@0"
            ]
        }
    ]}